<?xml version="1.0" ?>
<robot name="plane">

  <material name="grey">
    <color rgba=".7 .7 .7 1"/>
  </material> 

  <material name="green">
    <color rgba=".1 .8 .1 1"/>
  </material> 

  <material name="blue">
    <color rgba=".3 .5 .8 1"/>
  </material> 

  <material name="red">
    <color rgba=".9 .1 .1 1"/>
  </material> 
  
  <joint name="plane/imu_joint" type="fixed">
    <parent link="base_link"/>
    <child link="plane/imu_link"/>
    <origin xyz="0    0    0.246" rpy="0 0 0"/>
    <axis xyz="1 0 0"/>
    <limit lower="0.0" upper="0.0" effort="0.0" velocity="0.0"/>
  </joint>
  <joint name="airspeed_joint" type="fixed">
    <parent link="base_link"/>
    <child link="airspeed__link"/>
    <origin xyz="0    0    0.246" rpy="0 0 0"/>
    <axis xyz="0 0 0"/>
    <limit lower="0" upper="0" effort="0" velocity="0"/>
  </joint>
  <joint name="rotor_puller_joint" type="revolute">
    <parent link="base_link"/>
    <child link="rotor_puller"/>
    <origin xyz="1.57   0    1.0" rpy="0   1.57 0"/>
    <axis xyz="7.9e-04 0.0e+00 1.0e+00"/>
    <limit lower="-1e+16" upper="1e+16" effort="0.0" velocity="0.0"/>
  </joint>
  <joint name="left_elevon_joint" type="fixed">
    <parent link="base_link"/>
    <child link="left_elevon"/>
    <origin xyz="-0.07   0.4    0.326" rpy="0 0 0"/>
    <axis xyz="0 1 0"/>
    <limit lower="-0.53" upper="0.53" effort="0.0" velocity="0.0"/>
  </joint>
  <joint name="right_elevon_joint" type="fixed">
    <parent link="base_link"/>
    <child link="right_elevon"/>
    <origin xyz="-0.07  -0.4    0.326" rpy="0 0 0"/>
    <axis xyz="0 1 0"/>
    <limit lower="-0.53" upper="0.53" effort="0.0" velocity="0.0"/>
  </joint>
  <joint name="left_flap_joint" type="fixed">
    <parent link="base_link"/>
    <child link="left_flap"/>
    <origin xyz="-0.07   0.2    0.326" rpy="0 0 0"/>
    <axis xyz="0 1 0"/>
    <limit lower="-0.53" upper="0.53" effort="0.0" velocity="0.0"/>
  </joint>
  <joint name="right_flap_joint" type="fixed">
    <parent link="base_link"/>
    <child link="right_flap"/>
    <origin xyz="-0.07  -0.2    0.326" rpy="0 0 0"/>
    <axis xyz="0 1 0"/>
    <limit lower="-0.53" upper="0.53" effort="0.0" velocity="0.0"/>
  </joint>
  <joint name="elevator_joint" type="fixed">
    <parent link="base_link"/>
    <child link="elevator"/>
    <origin xyz="-0.5    0     0.246" rpy="0 0 0"/>
    <axis xyz="0 1 0"/>
    <limit lower="-0.53" upper="0.53" effort="0.0" velocity="0.0"/>
  </joint>
  <joint name="rudder_joint" type="fixed">
    <parent link="base_link"/>
    <child link="rudder"/>
    <origin xyz="-0.5    0     0.296" rpy="0 0 0"/>
    <axis xyz="0 0 1"/>
    <limit lower="-0.53" upper="0.53" effort="0.0" velocity="0.0"/>
  </joint>

  <link name="base_link">
    <!-- <inertial>
      <mass value="1.5"/>
      <origin xyz="0 0 0" rpy="0 0 0"/>
      <inertia ixx="0.197563" ixy="0" ixz="0" iyy="0.1458929" iyz="0" izz="0.1477"/>
    </inertial> -->
    <collision name="base_link_collision">
      <origin xyz="0    0    0.176" rpy="0 0 0"/>
      <geometry>
        <box size="0.47 0.47 0.11"/>
      </geometry>
    </collision>
    <visual name="base_link_visual">
      <origin xyz="0.07  0    0.166" rpy="0 0 0"/>
      <geometry>
        <mesh filename="package://fw_plane/model/meshes/body.stl" scale="0.025 0.025 0.025"/>
      </geometry>
      <!--material name="red"/--> <!-- Added by Peixuan Shu -->
    </visual>
  </link>
  <link name="plane/imu_link">
    <inertial>
      <mass value="0.015"/>
      <origin xyz="0 0 0" rpy="0 0 0"/>
      <inertia ixx="1e-05" ixy="0" ixz="0" iyy="1e-05" iyz="0" izz="1e-05"/>
    </inertial>
  </link>
  <link name="rotor_puller">
    <inertial>
      <mass value="0.005"/>
      <origin xyz="0 0 0" rpy="0 0 0"/>
      <inertia ixx="9.75e-07" ixy="0" ixz="0" iyy="0.000166704" iyz="0" izz="0.000167604"/>
    </inertial>
    <collision name="rotor_puller_collision">
      <origin xyz="0 0 0" rpy="0 0 0"/>
      <geometry>
        <cylinder radius="0.1" length="0.005"/>
      </geometry>
    </collision>
    <visual name="rotor_puller_visual">
      <origin xyz="0    0   -0.09" rpy="1.57 0 0"/>
      <geometry>
        <mesh filename="package://fw_plane/model/meshes/iris_prop_ccw.stl" scale="10 10 10"/>
      </geometry>
      <material name="grey"/> <!-- Added by Peixuan Shu -->
    </visual>
  </link>
  <link name="left_elevon">
    <inertial>
      <mass value="0.00000001"/>
      <origin xyz="0  0.3 0" rpy="0 0 0"/>
      <inertia ixx="0.000001" ixy="0.0" ixz="0.0" iyy="0.000001" iyz="0.0" izz="0.000001"/>
    </inertial>
    <visual name="left_elevon_visual">
      <origin xyz="0.14 -0.4  -0.16" rpy="1.57 0 0"/>
      <geometry>
        <mesh filename="package://fw_plane/model/meshes/left_aileron.stl" scale="0.025 0.025 0.025"/>
      </geometry>
      <material name="grey"/> <!-- Added by Peixuan Shu -->
    </visual>
  </link>
  <link name="right_elevon">
    <inertial>
      <mass value="0.00000001"/>
      <origin xyz="0  -0.3  0" rpy="0 0 0"/>
      <inertia ixx="0.000001" ixy="0.0" ixz="0.0" iyy="0.000001" iyz="0.0" izz="0.000001"/>
    </inertial>
    <visual name="right_elevon_visual">
      <origin xyz="0.14  0.4  -0.16" rpy="1.57 0 0"/>
      <geometry>
        <mesh filename="package://fw_plane/model/meshes/right_aileron.stl" scale="0.025 0.025 0.025"/>
      </geometry>
      <material name="grey"/> <!-- Added by Peixuan Shu -->
    </visual>
  </link>
  <link name="left_flap">
    <inertial>
      <mass value="0.00000001"/>
      <origin xyz="0   0.15 0" rpy="0 0 0"/>
      <inertia ixx="0.000001" ixy="0.0" ixz="0.0" iyy="0.000001" iyz="0.0" izz="0.000001"/>
    </inertial>
    <visual name="left_flap_visual">
      <origin xyz="0.14 -0.2  -0.16" rpy="1.57 0 0"/>
      <geometry>
        <mesh filename="package://fw_plane/model/meshes/left_flap.stl" scale="0.025 0.025 0.025"/>
      </geometry>
      <material name="grey"/> <!-- Added by Peixuan Shu -->
    </visual>
  </link>
  <link name="right_flap">
    <inertial>
      <mass value="0.00000001"/>
      <origin xyz="0   -0.15  0" rpy="0 0 0"/>
      <inertia ixx="0.000001" ixy="0.0" ixz="0.0" iyy="0.000001" iyz="0.0" izz="0.000001"/>
    </inertial>
    <visual name="right_flap_visual">
      <origin xyz="0.14  0.2  -0.16" rpy="1.57 0 0"/>
      <geometry>
        <mesh filename="package://fw_plane/model/meshes/right_flap.stl" scale="0.025 0.025 0.025"/>
      </geometry>
      <material name="grey"/> <!-- Added by Peixuan Shu -->
    </visual>
  </link>
  <link name="elevator">
    <inertial>
      <mass value="0.00000001"/>
      <origin xyz="-0.5  0   0" rpy="0 0 0"/>
      <inertia ixx="0.000001" ixy="0.0" ixz="0.0" iyy="0.000001" iyz="0.0" izz="0.000001"/>
    </inertial>
    <visual name="elevator_visual">
      <origin xyz="0.56999  0      -0.08" rpy="1.57 0 0"/>
      <geometry>
        <mesh filename="package://fw_plane/model/meshes/elevators.stl" scale="0.025 0.025 0.025"/>
      </geometry>
      <material name="grey"/> <!-- Added by Peixuan Shu -->
    </visual>
  </link>
  <link name="rudder">
    <inertial>
      <mass value="0.00000001"/>
      <origin xyz="-0.5   0    0.05" rpy="0 0 0"/>
      <inertia ixx="0.000001" ixy="0.0" ixz="0.0" iyy="0.000001" iyz="0.0" izz="0.000001"/>
    </inertial>
    <visual name="rudder_visual">
      <origin xyz="0.56999  0      -0.13" rpy="1.57 0 0"/>
      <geometry>
        <mesh filename="package://fw_plane/model/meshes/rudder.stl" scale="0.025 0.025 0.025"/>
      </geometry>
      <material name="grey"/> <!-- Added by Peixuan Shu -->
    </visual>
  </link>
  <link name="airspeed__link">
    <inertial>
      <mass value="0.015"/>
      <origin xyz="0 0 0" rpy="0 0 0"/>
      <inertia ixx="1e-05" ixy="0" ixz="0" iyy="1e-05" iyz="0" izz="1e-05"/>
    </inertial>
    <visual name="airspeed__visual">
      <origin xyz="0 0 0" rpy="0   1.57 0"/>
      <geometry>
        <cylinder radius="0.004" length="0.08"/>
      </geometry>
    </visual>
  </link>
</robot>
